<robot name="foosball_table">
  <material name="black">
    <color rgba="0.1 0.1 0.1 1.0"/>
  </material>
  <material name="green">
    <color rgba="0.1 0.4 0.1 1.0"/>
  </material>
  <material name="silver">
    <color rgba="0.5 0.5 0.5 1.0"/>
  </material>
  <material name="yellow">
    <color rgba="0.9 0.9 0.1 1.0"/>
  </material>
  <link name="table">
    <inertial>
      <mass value="1"/>
      <inertia ixx="1" ixy="0" ixz="0" iyy="1" iyz="0" izz="1"/>
    </inertial>
    <visual>
      <origin xyz="0.000000 -0.355600 0.000000" rpy="0 0 0"/>
      <geometry>
        <box size="1.219200 0.025400 0.158750"/>
      </geometry>
      <material name="black"/>
    </visual>
    <collision>
      <origin xyz="0.000000 -0.355600 0.000000" rpy="0 0 0"/>
      <geometry>
        <box size="1.219200 0.025400 0.158750"/>
      </geometry>
    </collision>
    <visual>
      <origin xyz="0.000000 0.355600 0.000000" rpy="0 0 0"/>
      <geometry>
        <box size="1.219200 0.025400 0.158750"/>
      </geometry>
      <material name="black"/>
    </visual>
    <collision>
      <origin xyz="0.000000 0.355600 0.000000" rpy="0 0 0"/>
      <geometry>
        <box size="1.219200 0.025400 0.158750"/>
      </geometry>
    </collision>
    <visual>
      <origin xyz="-0.622300 0.000000 0.000000" rpy="0 0 0"/>
      <geometry>
        <box size="0.025400 0.736600 0.158750"/>
      </geometry>
      <material name="black"/>
    </visual>
    <collision>
      <origin xyz="-0.622300 0.000000 0.000000" rpy="0 0 0"/>
      <geometry>
        <box size="0.025400 0.736600 0.158750"/>
      </geometry>
    </collision>
    <visual>
      <origin xyz="0.622300 0.000000 0.000000" rpy="0 0 0"/>
      <geometry>
        <box size="0.025400 0.736600 0.158750"/>
      </geometry>
      <material name="black"/>
    </visual>
    <collision>
      <origin xyz="0.622300 0.000000 0.000000" rpy="0 0 0"/>
      <geometry>
        <box size="0.025400 0.736600 0.158750"/>
      </geometry>
    </collision>
  </link>
  <link name="floor">
    <inertial>
      <mass value="1"/>
      <inertia ixx="1" ixy="0" ixz="0" iyy="1" iyz="0" izz="1"/>
    </inertial>
    <visual>
      <origin xyz="0.000000 0.000000 -0.092075" rpy="0 0 0"/>
      <geometry>
        <box size="1.270000 0.736600 0.025400"/>
      </geometry>
      <material name="green"/>
    </visual>
    <collision>
      <origin xyz="0.000000 0.000000 -0.092075" rpy="0 0 0"/>
      <geometry>
        <box size="1.270000 0.736600 0.025400"/>
      </geometry>
    </collision>
  </link>
  <joint name="floor_joint" type="fixed">
    <origin xyz="0.000000 0.000000 0.000000" rpy="0 0 0"/>
    <parent link="table"/>
    <child link="floor"/>
  </joint>
  <link name="rod1">
    <inertial>
      <mass value="1"/>
      <inertia ixx="1" ixy="0" ixz="0" iyy="1" iyz="0" izz="1"/>
    </inertial>
    <visual>
      <origin xyz="-0.533400 0.000000 0.000000" rpy="1.570796 0 0"/>
      <geometry>
        <cylinder radius="0.009525" length="1.524000"/>
      </geometry>
      <material name="silver"/>
    </visual>
  </link>
  <joint name="rod1_joint" type="prismatic">
    <axis xyz="0 1 0"/>
    <parent link="table"/>
    <child link="rod1"/>
    <limit effort="100" velocity="100"/>
  </joint>
  <link name="rod1_man0">
    <inertial>
      <mass value="1"/>
      <inertia ixx="1" ixy="0" ixz="0" iyy="1" iyz="0" izz="1"/>
    </inertial>
    <visual>
      <origin xyz="0.000000 0.000000 -0.025400" rpy="0 0 0"/>
      <geometry>
        <box size="0.012700 0.025400 0.101600"/>
      </geometry>
      <material name="yellow"/>
    </visual>
    <collision>
      <origin xyz="0.000000 0.000000 -0.025400" rpy="0 0 0"/>
      <geometry>
        <box size="0.012700 0.025400 0.101600"/>
      </geometry>
    </collision>
  </link>
  <joint name="rod1_man0_joint" type="continuous">
    <origin xyz="-0.533400 -0.206375 0.000000" rpy="0 0 0"/>
    <axis xyz="0 1 0"/>
    <parent link="rod1"/>
    <child link="rod1_man0"/>
    <limit effort="100" velocity="100"/>
  </joint>
  <link name="rod1_man1">
    <inertial>
      <mass value="1"/>
      <inertia ixx="1" ixy="0" ixz="0" iyy="1" iyz="0" izz="1"/>
    </inertial>
    <visual>
      <origin xyz="0.000000 0.000000 -0.025400" rpy="0 0 0"/>
      <geometry>
        <box size="0.012700 0.025400 0.101600"/>
      </geometry>
      <material name="yellow"/>
    </visual>
    <collision>
      <origin xyz="0.000000 0.000000 -0.025400" rpy="0 0 0"/>
      <geometry>
        <box size="0.012700 0.025400 0.101600"/>
      </geometry>
    </collision>
  </link>
  <joint name="rod1_man1_joint" type="fixed">
    <origin xyz="0.000000 0.206375 0.000000" rpy="0 0 0"/>
    <parent link="rod1_man0"/>
    <child link="rod1_man1"/>
  </joint>
  <link name="rod1_man2">
    <inertial>
      <mass value="1"/>
      <inertia ixx="1" ixy="0" ixz="0" iyy="1" iyz="0" izz="1"/>
    </inertial>
    <visual>
      <origin xyz="0.000000 0.000000 -0.025400" rpy="0 0 0"/>
      <geometry>
        <box size="0.012700 0.025400 0.101600"/>
      </geometry>
      <material name="yellow"/>
    </visual>
    <collision>
      <origin xyz="0.000000 0.000000 -0.025400" rpy="0 0 0"/>
      <geometry>
        <box size="0.012700 0.025400 0.101600"/>
      </geometry>
    </collision>
  </link>
  <joint name="rod1_man2_joint" type="fixed">
    <origin xyz="0.000000 0.412750 0.000000" rpy="0 0 0"/>
    <parent link="rod1_man0"/>
    <child link="rod1_man2"/>
  </joint>
  <link name="rod2">
    <inertial>
      <mass value="1"/>
      <inertia ixx="1" ixy="0" ixz="0" iyy="1" iyz="0" izz="1"/>
    </inertial>
    <visual>
      <origin xyz="-0.381000 0.000000 0.000000" rpy="1.570796 0 0"/>
      <geometry>
        <cylinder radius="0.009525" length="1.524000"/>
      </geometry>
      <material name="silver"/>
    </visual>
  </link>
  <joint name="rod2_joint" type="prismatic">
    <axis xyz="0 1 0"/>
    <parent link="table"/>
    <child link="rod2"/>
    <limit effort="100" velocity="100"/>
  </joint>
  <link name="rod2_man0">
    <inertial>
      <mass value="1"/>
      <inertia ixx="1" ixy="0" ixz="0" iyy="1" iyz="0" izz="1"/>
    </inertial>
    <visual>
      <origin xyz="0.000000 0.000000 -0.025400" rpy="0 0 0"/>
      <geometry>
        <box size="0.012700 0.025400 0.101600"/>
      </geometry>
      <material name="yellow"/>
    </visual>
    <collision>
      <origin xyz="0.000000 0.000000 -0.025400" rpy="0 0 0"/>
      <geometry>
        <box size="0.012700 0.025400 0.101600"/>
      </geometry>
    </collision>
  </link>
  <joint name="rod2_man0_joint" type="continuous">
    <origin xyz="-0.381000 -0.120650 0.000000" rpy="0 0 0"/>
    <axis xyz="0 1 0"/>
    <parent link="rod2"/>
    <child link="rod2_man0"/>
    <limit effort="100" velocity="100"/>
  </joint>
  <link name="rod2_man1">
    <inertial>
      <mass value="1"/>
      <inertia ixx="1" ixy="0" ixz="0" iyy="1" iyz="0" izz="1"/>
    </inertial>
    <visual>
      <origin xyz="0.000000 0.000000 -0.025400" rpy="0 0 0"/>
      <geometry>
        <box size="0.012700 0.025400 0.101600"/>
      </geometry>
      <material name="yellow"/>
    </visual>
    <collision>
      <origin xyz="0.000000 0.000000 -0.025400" rpy="0 0 0"/>
      <geometry>
        <box size="0.012700 0.025400 0.101600"/>
      </geometry>
    </collision>
  </link>
  <joint name="rod2_man1_joint" type="fixed">
    <origin xyz="0.000000 0.241300 0.000000" rpy="0 0 0"/>
    <parent link="rod2_man0"/>
    <child link="rod2_man1"/>
  </joint>
  <link name="rod3">
    <inertial>
      <mass value="1"/>
      <inertia ixx="1" ixy="0" ixz="0" iyy="1" iyz="0" izz="1"/>
    </inertial>
    <visual>
      <origin xyz="-0.228600 0.000000 0.000000" rpy="1.570796 0 0"/>
      <geometry>
        <cylinder radius="0.009525" length="1.524000"/>
      </geometry>
      <material name="silver"/>
    </visual>
  </link>
  <joint name="rod3_joint" type="prismatic">
    <axis xyz="0 1 0"/>
    <parent link="table"/>
    <child link="rod3"/>
    <limit effort="100" velocity="100"/>
  </joint>
  <link name="rod3_man0">
    <inertial>
      <mass value="1"/>
      <inertia ixx="1" ixy="0" ixz="0" iyy="1" iyz="0" izz="1"/>
    </inertial>
    <visual>
      <origin xyz="0.000000 0.000000 -0.025400" rpy="0 0 0"/>
      <geometry>
        <box size="0.012700 0.025400 0.101600"/>
      </geometry>
      <material name="black"/>
    </visual>
    <collision>
      <origin xyz="0.000000 0.000000 -0.025400" rpy="0 0 0"/>
      <geometry>
        <box size="0.012700 0.025400 0.101600"/>
      </geometry>
    </collision>
  </link>
  <joint name="rod3_man0_joint" type="continuous">
    <origin xyz="-0.228600 -0.184150 0.000000" rpy="0 0 0"/>
    <axis xyz="0 1 0"/>
    <parent link="rod3"/>
    <child link="rod3_man0"/>
    <limit effort="100" velocity="100"/>
  </joint>
  <link name="rod3_man1">
    <inertial>
      <mass value="1"/>
      <inertia ixx="1" ixy="0" ixz="0" iyy="1" iyz="0" izz="1"/>
    </inertial>
    <visual>
      <origin xyz="0.000000 0.000000 -0.025400" rpy="0 0 0"/>
      <geometry>
        <box size="0.012700 0.025400 0.101600"/>
      </geometry>
      <material name="black"/>
    </visual>
    <collision>
      <origin xyz="0.000000 0.000000 -0.025400" rpy="0 0 0"/>
      <geometry>
        <box size="0.012700 0.025400 0.101600"/>
      </geometry>
    </collision>
  </link>
  <joint name="rod3_man1_joint" type="fixed">
    <origin xyz="0.000000 0.184150 0.000000" rpy="0 0 0"/>
    <parent link="rod3_man0"/>
    <child link="rod3_man1"/>
  </joint>
  <link name="rod3_man2">
    <inertial>
      <mass value="1"/>
      <inertia ixx="1" ixy="0" ixz="0" iyy="1" iyz="0" izz="1"/>
    </inertial>
    <visual>
      <origin xyz="0.000000 0.000000 -0.025400" rpy="0 0 0"/>
      <geometry>
        <box size="0.012700 0.025400 0.101600"/>
      </geometry>
      <material name="black"/>
    </visual>
    <collision>
      <origin xyz="0.000000 0.000000 -0.025400" rpy="0 0 0"/>
      <geometry>
        <box size="0.012700 0.025400 0.101600"/>
      </geometry>
    </collision>
  </link>
  <joint name="rod3_man2_joint" type="fixed">
    <origin xyz="0.000000 0.368300 0.000000" rpy="0 0 0"/>
    <parent link="rod3_man0"/>
    <child link="rod3_man2"/>
  </joint>
  <link name="rod4">
    <inertial>
      <mass value="1"/>
      <inertia ixx="1" ixy="0" ixz="0" iyy="1" iyz="0" izz="1"/>
    </inertial>
    <visual>
      <origin xyz="-0.076200 0.000000 0.000000" rpy="1.570796 0 0"/>
      <geometry>
        <cylinder radius="0.009525" length="1.524000"/>
      </geometry>
      <material name="silver"/>
    </visual>
  </link>
  <joint name="rod4_joint" type="prismatic">
    <axis xyz="0 1 0"/>
    <parent link="table"/>
    <child link="rod4"/>
    <limit effort="100" velocity="100"/>
  </joint>
  <link name="rod4_man0">
    <inertial>
      <mass value="1"/>
      <inertia ixx="1" ixy="0" ixz="0" iyy="1" iyz="0" izz="1"/>
    </inertial>
    <visual>
      <origin xyz="0.000000 0.000000 -0.025400" rpy="0 0 0"/>
      <geometry>
        <box size="0.012700 0.025400 0.101600"/>
      </geometry>
      <material name="yellow"/>
    </visual>
    <collision>
      <origin xyz="0.000000 0.000000 -0.025400" rpy="0 0 0"/>
      <geometry>
        <box size="0.012700 0.025400 0.101600"/>
      </geometry>
    </collision>
  </link>
  <joint name="rod4_man0_joint" type="continuous">
    <origin xyz="-0.076200 -0.241300 0.000000" rpy="0 0 0"/>
    <axis xyz="0 1 0"/>
    <parent link="rod4"/>
    <child link="rod4_man0"/>
    <limit effort="100" velocity="100"/>
  </joint>
  <link name="rod4_man1">
    <inertial>
      <mass value="1"/>
      <inertia ixx="1" ixy="0" ixz="0" iyy="1" iyz="0" izz="1"/>
    </inertial>
    <visual>
      <origin xyz="0.000000 0.000000 -0.025400" rpy="0 0 0"/>
      <geometry>
        <box size="0.012700 0.025400 0.101600"/>
      </geometry>
      <material name="yellow"/>
    </visual>
    <collision>
      <origin xyz="0.000000 0.000000 -0.025400" rpy="0 0 0"/>
      <geometry>
        <box size="0.012700 0.025400 0.101600"/>
      </geometry>
    </collision>
  </link>
  <joint name="rod4_man1_joint" type="fixed">
    <origin xyz="0.000000 0.120650 0.000000" rpy="0 0 0"/>
    <parent link="rod4_man0"/>
    <child link="rod4_man1"/>
  </joint>
  <link name="rod4_man2">
    <inertial>
      <mass value="1"/>
      <inertia ixx="1" ixy="0" ixz="0" iyy="1" iyz="0" izz="1"/>
    </inertial>
    <visual>
      <origin xyz="0.000000 0.000000 -0.025400" rpy="0 0 0"/>
      <geometry>
        <box size="0.012700 0.025400 0.101600"/>
      </geometry>
      <material name="yellow"/>
    </visual>
    <collision>
      <origin xyz="0.000000 0.000000 -0.025400" rpy="0 0 0"/>
      <geometry>
        <box size="0.012700 0.025400 0.101600"/>
      </geometry>
    </collision>
  </link>
  <joint name="rod4_man2_joint" type="fixed">
    <origin xyz="0.000000 0.241300 0.000000" rpy="0 0 0"/>
    <parent link="rod4_man0"/>
    <child link="rod4_man2"/>
  </joint>
  <link name="rod4_man3">
    <inertial>
      <mass value="1"/>
      <inertia ixx="1" ixy="0" ixz="0" iyy="1" iyz="0" izz="1"/>
    </inertial>
    <visual>
      <origin xyz="0.000000 0.000000 -0.025400" rpy="0 0 0"/>
      <geometry>
        <box size="0.012700 0.025400 0.101600"/>
      </geometry>
      <material name="yellow"/>
    </visual>
    <collision>
      <origin xyz="0.000000 0.000000 -0.025400" rpy="0 0 0"/>
      <geometry>
        <box size="0.012700 0.025400 0.101600"/>
      </geometry>
    </collision>
  </link>
  <joint name="rod4_man3_joint" type="fixed">
    <origin xyz="0.000000 0.361950 0.000000" rpy="0 0 0"/>
    <parent link="rod4_man0"/>
    <child link="rod4_man3"/>
  </joint>
  <link name="rod4_man4">
    <inertial>
      <mass value="1"/>
      <inertia ixx="1" ixy="0" ixz="0" iyy="1" iyz="0" izz="1"/>
    </inertial>
    <visual>
      <origin xyz="0.000000 0.000000 -0.025400" rpy="0 0 0"/>
      <geometry>
        <box size="0.012700 0.025400 0.101600"/>
      </geometry>
      <material name="yellow"/>
    </visual>
    <collision>
      <origin xyz="0.000000 0.000000 -0.025400" rpy="0 0 0"/>
      <geometry>
        <box size="0.012700 0.025400 0.101600"/>
      </geometry>
    </collision>
  </link>
  <joint name="rod4_man4_joint" type="fixed">
    <origin xyz="0.000000 0.482600 0.000000" rpy="0 0 0"/>
    <parent link="rod4_man0"/>
    <child link="rod4_man4"/>
  </joint>
  <link name="rod5">
    <inertial>
      <mass value="1"/>
      <inertia ixx="1" ixy="0" ixz="0" iyy="1" iyz="0" izz="1"/>
    </inertial>
    <visual>
      <origin xyz="0.076200 0.000000 0.000000" rpy="1.570796 0 0"/>
      <geometry>
        <cylinder radius="0.009525" length="1.524000"/>
      </geometry>
      <material name="silver"/>
    </visual>
  </link>
  <joint name="rod5_joint" type="prismatic">
    <axis xyz="0 1 0"/>
    <parent link="table"/>
    <child link="rod5"/>
    <limit effort="100" velocity="100"/>
  </joint>
  <link name="rod5_man0">
    <inertial>
      <mass value="1"/>
      <inertia ixx="1" ixy="0" ixz="0" iyy="1" iyz="0" izz="1"/>
    </inertial>
    <visual>
      <origin xyz="0.000000 0.000000 -0.025400" rpy="0 0 0"/>
      <geometry>
        <box size="0.012700 0.025400 0.101600"/>
      </geometry>
      <material name="black"/>
    </visual>
    <collision>
      <origin xyz="0.000000 0.000000 -0.025400" rpy="0 0 0"/>
      <geometry>
        <box size="0.012700 0.025400 0.101600"/>
      </geometry>
    </collision>
  </link>
  <joint name="rod5_man0_joint" type="continuous">
    <origin xyz="0.076200 -0.241300 0.000000" rpy="0 0 0"/>
    <axis xyz="0 1 0"/>
    <parent link="rod5"/>
    <child link="rod5_man0"/>
    <limit effort="100" velocity="100"/>
  </joint>
  <link name="rod5_man1">
    <inertial>
      <mass value="1"/>
      <inertia ixx="1" ixy="0" ixz="0" iyy="1" iyz="0" izz="1"/>
    </inertial>
    <visual>
      <origin xyz="0.000000 0.000000 -0.025400" rpy="0 0 0"/>
      <geometry>
        <box size="0.012700 0.025400 0.101600"/>
      </geometry>
      <material name="black"/>
    </visual>
    <collision>
      <origin xyz="0.000000 0.000000 -0.025400" rpy="0 0 0"/>
      <geometry>
        <box size="0.012700 0.025400 0.101600"/>
      </geometry>
    </collision>
  </link>
  <joint name="rod5_man1_joint" type="fixed">
    <origin xyz="0.000000 0.120650 0.000000" rpy="0 0 0"/>
    <parent link="rod5_man0"/>
    <child link="rod5_man1"/>
  </joint>
  <link name="rod5_man2">
    <inertial>
      <mass value="1"/>
      <inertia ixx="1" ixy="0" ixz="0" iyy="1" iyz="0" izz="1"/>
    </inertial>
    <visual>
      <origin xyz="0.000000 0.000000 -0.025400" rpy="0 0 0"/>
      <geometry>
        <box size="0.012700 0.025400 0.101600"/>
      </geometry>
      <material name="black"/>
    </visual>
    <collision>
      <origin xyz="0.000000 0.000000 -0.025400" rpy="0 0 0"/>
      <geometry>
        <box size="0.012700 0.025400 0.101600"/>
      </geometry>
    </collision>
  </link>
  <joint name="rod5_man2_joint" type="fixed">
    <origin xyz="0.000000 0.241300 0.000000" rpy="0 0 0"/>
    <parent link="rod5_man0"/>
    <child link="rod5_man2"/>
  </joint>
  <link name="rod5_man3">
    <inertial>
      <mass value="1"/>
      <inertia ixx="1" ixy="0" ixz="0" iyy="1" iyz="0" izz="1"/>
    </inertial>
    <visual>
      <origin xyz="0.000000 0.000000 -0.025400" rpy="0 0 0"/>
      <geometry>
        <box size="0.012700 0.025400 0.101600"/>
      </geometry>
      <material name="black"/>
    </visual>
    <collision>
      <origin xyz="0.000000 0.000000 -0.025400" rpy="0 0 0"/>
      <geometry>
        <box size="0.012700 0.025400 0.101600"/>
      </geometry>
    </collision>
  </link>
  <joint name="rod5_man3_joint" type="fixed">
    <origin xyz="0.000000 0.361950 0.000000" rpy="0 0 0"/>
    <parent link="rod5_man0"/>
    <child link="rod5_man3"/>
  </joint>
  <link name="rod5_man4">
    <inertial>
      <mass value="1"/>
      <inertia ixx="1" ixy="0" ixz="0" iyy="1" iyz="0" izz="1"/>
    </inertial>
    <visual>
      <origin xyz="0.000000 0.000000 -0.025400" rpy="0 0 0"/>
      <geometry>
        <box size="0.012700 0.025400 0.101600"/>
      </geometry>
      <material name="black"/>
    </visual>
    <collision>
      <origin xyz="0.000000 0.000000 -0.025400" rpy="0 0 0"/>
      <geometry>
        <box size="0.012700 0.025400 0.101600"/>
      </geometry>
    </collision>
  </link>
  <joint name="rod5_man4_joint" type="fixed">
    <origin xyz="0.000000 0.482600 0.000000" rpy="0 0 0"/>
    <parent link="rod5_man0"/>
    <child link="rod5_man4"/>
  </joint>
  <link name="rod6">
    <inertial>
      <mass value="1"/>
      <inertia ixx="1" ixy="0" ixz="0" iyy="1" iyz="0" izz="1"/>
    </inertial>
    <visual>
      <origin xyz="0.228600 0.000000 0.000000" rpy="1.570796 0 0"/>
      <geometry>
        <cylinder radius="0.009525" length="1.524000"/>
      </geometry>
      <material name="silver"/>
    </visual>
  </link>
  <joint name="rod6_joint" type="prismatic">
    <axis xyz="0 1 0"/>
    <parent link="table"/>
    <child link="rod6"/>
    <limit effort="100" velocity="100"/>
  </joint>
  <link name="rod6_man0">
    <inertial>
      <mass value="1"/>
      <inertia ixx="1" ixy="0" ixz="0" iyy="1" iyz="0" izz="1"/>
    </inertial>
    <visual>
      <origin xyz="0.000000 0.000000 -0.025400" rpy="0 0 0"/>
      <geometry>
        <box size="0.012700 0.025400 0.101600"/>
      </geometry>
      <material name="yellow"/>
    </visual>
    <collision>
      <origin xyz="0.000000 0.000000 -0.025400" rpy="0 0 0"/>
      <geometry>
        <box size="0.012700 0.025400 0.101600"/>
      </geometry>
    </collision>
  </link>
  <joint name="rod6_man0_joint" type="continuous">
    <origin xyz="0.228600 -0.184150 0.000000" rpy="0 0 0"/>
    <axis xyz="0 1 0"/>
    <parent link="rod6"/>
    <child link="rod6_man0"/>
    <limit effort="100" velocity="100"/>
  </joint>
  <link name="rod6_man1">
    <inertial>
      <mass value="1"/>
      <inertia ixx="1" ixy="0" ixz="0" iyy="1" iyz="0" izz="1"/>
    </inertial>
    <visual>
      <origin xyz="0.000000 0.000000 -0.025400" rpy="0 0 0"/>
      <geometry>
        <box size="0.012700 0.025400 0.101600"/>
      </geometry>
      <material name="yellow"/>
    </visual>
    <collision>
      <origin xyz="0.000000 0.000000 -0.025400" rpy="0 0 0"/>
      <geometry>
        <box size="0.012700 0.025400 0.101600"/>
      </geometry>
    </collision>
  </link>
  <joint name="rod6_man1_joint" type="fixed">
    <origin xyz="0.000000 0.184150 0.000000" rpy="0 0 0"/>
    <parent link="rod6_man0"/>
    <child link="rod6_man1"/>
  </joint>
  <link name="rod6_man2">
    <inertial>
      <mass value="1"/>
      <inertia ixx="1" ixy="0" ixz="0" iyy="1" iyz="0" izz="1"/>
    </inertial>
    <visual>
      <origin xyz="0.000000 0.000000 -0.025400" rpy="0 0 0"/>
      <geometry>
        <box size="0.012700 0.025400 0.101600"/>
      </geometry>
      <material name="yellow"/>
    </visual>
    <collision>
      <origin xyz="0.000000 0.000000 -0.025400" rpy="0 0 0"/>
      <geometry>
        <box size="0.012700 0.025400 0.101600"/>
      </geometry>
    </collision>
  </link>
  <joint name="rod6_man2_joint" type="fixed">
    <origin xyz="0.000000 0.368300 0.000000" rpy="0 0 0"/>
    <parent link="rod6_man0"/>
    <child link="rod6_man2"/>
  </joint>
  <link name="rod7">
    <inertial>
      <mass value="1"/>
      <inertia ixx="1" ixy="0" ixz="0" iyy="1" iyz="0" izz="1"/>
    </inertial>
    <visual>
      <origin xyz="0.381000 0.000000 0.000000" rpy="1.570796 0 0"/>
      <geometry>
        <cylinder radius="0.009525" length="1.524000"/>
      </geometry>
      <material name="silver"/>
    </visual>
  </link>
  <joint name="rod7_joint" type="prismatic">
    <axis xyz="0 1 0"/>
    <parent link="table"/>
    <child link="rod7"/>
    <limit effort="100" velocity="100"/>
  </joint>
  <link name="rod7_man0">
    <inertial>
      <mass value="1"/>
      <inertia ixx="1" ixy="0" ixz="0" iyy="1" iyz="0" izz="1"/>
    </inertial>
    <visual>
      <origin xyz="0.000000 0.000000 -0.025400" rpy="0 0 0"/>
      <geometry>
        <box size="0.012700 0.025400 0.101600"/>
      </geometry>
      <material name="black"/>
    </visual>
    <collision>
      <origin xyz="0.000000 0.000000 -0.025400" rpy="0 0 0"/>
      <geometry>
        <box size="0.012700 0.025400 0.101600"/>
      </geometry>
    </collision>
  </link>
  <joint name="rod7_man0_joint" type="continuous">
    <origin xyz="0.381000 -0.120650 0.000000" rpy="0 0 0"/>
    <axis xyz="0 1 0"/>
    <parent link="rod7"/>
    <child link="rod7_man0"/>
    <limit effort="100" velocity="100"/>
  </joint>
  <link name="rod7_man1">
    <inertial>
      <mass value="1"/>
      <inertia ixx="1" ixy="0" ixz="0" iyy="1" iyz="0" izz="1"/>
    </inertial>
    <visual>
      <origin xyz="0.000000 0.000000 -0.025400" rpy="0 0 0"/>
      <geometry>
        <box size="0.012700 0.025400 0.101600"/>
      </geometry>
      <material name="black"/>
    </visual>
    <collision>
      <origin xyz="0.000000 0.000000 -0.025400" rpy="0 0 0"/>
      <geometry>
        <box size="0.012700 0.025400 0.101600"/>
      </geometry>
    </collision>
  </link>
  <joint name="rod7_man1_joint" type="fixed">
    <origin xyz="0.000000 0.241300 0.000000" rpy="0 0 0"/>
    <parent link="rod7_man0"/>
    <child link="rod7_man1"/>
  </joint>
  <link name="rod8">
    <inertial>
      <mass value="1"/>
      <inertia ixx="1" ixy="0" ixz="0" iyy="1" iyz="0" izz="1"/>
    </inertial>
    <visual>
      <origin xyz="0.533400 0.000000 0.000000" rpy="1.570796 0 0"/>
      <geometry>
        <cylinder radius="0.009525" length="1.524000"/>
      </geometry>
      <material name="silver"/>
    </visual>
  </link>
  <joint name="rod8_joint" type="prismatic">
    <axis xyz="0 1 0"/>
    <parent link="table"/>
    <child link="rod8"/>
    <limit effort="100" velocity="100"/>
  </joint>
  <link name="rod8_man0">
    <inertial>
      <mass value="1"/>
      <inertia ixx="1" ixy="0" ixz="0" iyy="1" iyz="0" izz="1"/>
    </inertial>
    <visual>
      <origin xyz="0.000000 0.000000 -0.025400" rpy="0 0 0"/>
      <geometry>
        <box size="0.012700 0.025400 0.101600"/>
      </geometry>
      <material name="black"/>
    </visual>
    <collision>
      <origin xyz="0.000000 0.000000 -0.025400" rpy="0 0 0"/>
      <geometry>
        <box size="0.012700 0.025400 0.101600"/>
      </geometry>
    </collision>
  </link>
  <joint name="rod8_man0_joint" type="continuous">
    <origin xyz="0.533400 -0.206375 0.000000" rpy="0 0 0"/>
    <axis xyz="0 1 0"/>
    <parent link="rod8"/>
    <child link="rod8_man0"/>
    <limit effort="100" velocity="100"/>
  </joint>
  <link name="rod8_man1">
    <inertial>
      <mass value="1"/>
      <inertia ixx="1" ixy="0" ixz="0" iyy="1" iyz="0" izz="1"/>
    </inertial>
    <visual>
      <origin xyz="0.000000 0.000000 -0.025400" rpy="0 0 0"/>
      <geometry>
        <box size="0.012700 0.025400 0.101600"/>
      </geometry>
      <material name="black"/>
    </visual>
    <collision>
      <origin xyz="0.000000 0.000000 -0.025400" rpy="0 0 0"/>
      <geometry>
        <box size="0.012700 0.025400 0.101600"/>
      </geometry>
    </collision>
  </link>
  <joint name="rod8_man1_joint" type="fixed">
    <origin xyz="0.000000 0.206375 0.000000" rpy="0 0 0"/>
    <parent link="rod8_man0"/>
    <child link="rod8_man1"/>
  </joint>
  <link name="rod8_man2">
    <inertial>
      <mass value="1"/>
      <inertia ixx="1" ixy="0" ixz="0" iyy="1" iyz="0" izz="1"/>
    </inertial>
    <visual>
      <origin xyz="0.000000 0.000000 -0.025400" rpy="0 0 0"/>
      <geometry>
        <box size="0.012700 0.025400 0.101600"/>
      </geometry>
      <material name="black"/>
    </visual>
    <collision>
      <origin xyz="0.000000 0.000000 -0.025400" rpy="0 0 0"/>
      <geometry>
        <box size="0.012700 0.025400 0.101600"/>
      </geometry>
    </collision>
  </link>
  <joint name="rod8_man2_joint" type="fixed">
    <origin xyz="0.000000 0.412750 0.000000" rpy="0 0 0"/>
    <parent link="rod8_man0"/>
    <child link="rod8_man2"/>
  </joint>
</robot>
